<?xml version="1.0" encoding="utf-8"?>
<!-- This URDF was automatically created by SolidWorks to URDF Exporter! Originally created by Stephen Brawner (brawner@gmail.com) 
     Commit Version: 1.5.1-0-g916b5db  Build Version: 1.5.7152.31018
     For more information, please see http://wiki.ros.org/sw_urdf_exporter -->
<robot
  name="lide">
  <link
    name="base_link">
    <inertial>
      <origin
        xyz="-0.124039089703059 0.0849018285649875 0.0507049336382351"
        rpy="0 0 0" />
      <mass
        value="2.91745388040908" />
      <inertia
        ixx="0.00617452431631895"
        ixy="-7.15450905274655E-07"
        ixz="-1.26679487712579E-05"
        iyy="0.00553460681657008"
        iyz="-3.51329121715537E-07"
        izz="0.0110508759807573" />
    </inertial>
    <visual>
      <origin
        xyz="0 0 0"
        rpy="0 0 0" />
      <geometry>
        <mesh
          filename="package://lide/meshes/base_link.STL" />
      </geometry>
      <material
        name="">
        <color
          rgba="0.752941176470588 0.752941176470588 0.752941176470588 1" />
      </material>
    </visual>
    <collision>
      <origin
        xyz="0 0 0"
        rpy="0 0 0" />
      <geometry>
        <mesh
          filename="package://lide/meshes/base_link.STL" />
      </geometry>
    </collision>
  </link>
  <link
    name="LFS">
    <inertial>
      <origin
        xyz="0.0455604268709419 0.00830943309140331 0.00297622851896683"
        rpy="0 0 0" />
      <mass
        value="0.0727928435161986" />
      <inertia
        ixx="2.20927876796312E-05"
        ixy="-1.64845302056395E-08"
        ixz="-1.56454773175215E-07"
        iyy="1.62632133784213E-05"
        iyz="2.96411876511178E-09"
        izz="1.80843397531752E-05" />
    </inertial>
    <visual>
      <origin
        xyz="0 0 0"
        rpy="0 0 0" />
      <geometry>
        <mesh
          filename="package://lide/meshes/LFS.STL" />
      </geometry>
      <material
        name="">
        <color
          rgba="0.752941176470588 0.752941176470588 0.752941176470588 1" />
      </material>
    </visual>
    <collision>
      <origin
        xyz="0 0 0"
        rpy="0 0 0" />
      <geometry>
        <mesh
          filename="package://lide/meshes/LFS.STL" />
      </geometry>
    </collision>
  </link>
  <joint
    name="LFS"
    type="fixed">
    <origin
      xyz="-0.0540436140506676 0.182406433684605 -0.0365027479853973"
      rpy="1.5707963267949 0 1.5707963267949" />
    <parent
      link="base_link" />
    <child
      link="LFS" />
    <axis
      xyz="0 0 0" />
  </joint>
  <link
    name="LFW">
    <inertial>
      <origin
        xyz="0.015 0 3.46944695195361E-18"
        rpy="0 0 0" />
      <mass
        value="0.289786121963991" />
      <inertia
        ixx="0.000439831942427159"
        ixy="1.68397793185769E-22"
        ixz="-6.91311221044114E-21"
        iyy="0.000241649930360879"
        iyz="-3.3881317890172E-21"
        izz="0.000241649930360879" />
    </inertial>
    <visual>
      <origin
        xyz="0 0 0"
        rpy="0 0 0" />
      <geometry>
        <mesh
          filename="package://lide/meshes/LFW.STL" />
      </geometry>
      <material
        name="">
        <color
          rgba="1 1 1 1" />
      </material>
    </visual>
    <collision>
      <origin
        xyz="0 0 0"
        rpy="0 0 0" />
      <geometry>
        <mesh
          filename="package://lide/meshes/LFW.STL" />
      </geometry>
    </collision>
  </link>
  <joint
    name="LFW"
    type="continuous">
    <origin
      xyz="0.0633463599631527 -0.00679803845222953 0.0150436140506676"
      rpy="-1.62639053095063 0 0" />
    <parent
      link="LFS" />
    <child
      link="LFW" />
    <axis
      xyz="1 0 0" />
    <limit
      effort="3.1"
      velocity="7" />
  </joint>
  <link
    name="RFS">
    <inertial>
      <origin
        xyz="-0.0191828308457407 -0.00900932874707057 0.0520056318885905"
        rpy="0 0 0" />
      <mass
        value="0.0727928435161986" />
      <inertia
        ixx="2.20927876796313E-05"
        ixy="-1.64845302056314E-08"
        ixz="1.56454773175213E-07"
        iyy="1.62632133784213E-05"
        iyz="-2.96411876510415E-09"
        izz="1.80843397531752E-05" />
    </inertial>
    <visual>
      <origin
        xyz="0 0 0"
        rpy="0 0 0" />
      <geometry>
        <mesh
          filename="package://lide/meshes/RFS.STL" />
      </geometry>
      <material
        name="">
        <color
          rgba="0.752941176470588 0.752941176470588 0.752941176470588 1" />
      </material>
    </visual>
    <collision>
      <origin
        xyz="0 0 0"
        rpy="0 0 0" />
      <geometry>
        <mesh
          filename="package://lide/meshes/RFS.STL" />
      </geometry>
    </collision>
  </link>
  <joint
    name="RFS"
    type="fixed">
    <origin
      xyz="-0.103073017420291 -0.0427840297098062 -0.0192156081309485"
      rpy="1.5707963267949 0 1.5707963267949" />
    <parent
      link="base_link" />
    <child
      link="RFS" />
    <axis
      xyz="0 0 0" />
  </joint>
  <link
    name="RFW">
    <inertial>
      <origin
        xyz="-0.015 0 0"
        rpy="0 0 0" />
      <mass
        value="0.289786121963991" />
      <inertia
        ixx="0.000439831942427158"
        ixy="-4.65239694003277E-37"
        ixz="0"
        iyy="0.000241649930360878"
        iyz="3.02397073524909E-39"
        izz="0.000241649930360879" />
    </inertial>
    <visual>
      <origin
        xyz="0 0 0"
        rpy="0 0 0" />
      <geometry>
        <mesh
          filename="package://lide/meshes/RFW.STL" />
      </geometry>
      <material
        name="">
        <color
          rgba="1 1 1 1" />
      </material>
    </visual>
    <collision>
      <origin
        xyz="0 0 0"
        rpy="0 0 0" />
      <geometry>
        <mesh
          filename="package://lide/meshes/RFW.STL" />
      </geometry>
    </collision>
  </link>
  <joint
    name="RFW"
    type="continuous">
    <origin
      xyz="-0.0369687639379516 -0.0240836054314246 0.0640730174202912"
      rpy="0 0 0" />
    <parent
      link="RFS" />
    <child
      link="RFW" />
    <axis
      xyz="1 0 0" />
    <limit
      effort="3.1"
      velocity="7" />
  </joint>
  <link
    name="LBS">
    <inertial>
      <origin
        xyz="-4.7988246709707E-10 -0.023473389822872 -1.16815021544703E-09"
        rpy="0 0 0" />
      <mass
        value="0.083535872081433" />
      <inertia
        ixx="7.72968060896302E-05"
        ixy="-8.60478073469977E-13"
        ixz="1.40586674043926E-13"
        iyy="5.13820931926883E-05"
        iyz="-5.06559896269531E-12"
        izz="7.73952626484255E-05" />
    </inertial>
    <visual>
      <origin
        xyz="0 0 0"
        rpy="0 0 0" />
      <geometry>
        <mesh
          filename="package://lide/meshes/LBS.STL" />
      </geometry>
      <material
        name="">
        <color
          rgba="0.898039215686275 0.917647058823529 0.929411764705882 1" />
      </material>
    </visual>
    <collision>
      <origin
        xyz="0 0 0"
        rpy="0 0 0" />
      <geometry>
        <mesh
          filename="package://lide/meshes/LBS.STL" />
      </geometry>
    </collision>
  </link>
  <joint
    name="LBS"
    type="fixed">
    <origin
      xyz="-0.201999999999999 0.228002793647758 -0.0125623205686227"
      rpy="1.5707963267949 0 1.5707963267949" />
    <parent
      link="base_link" />
    <child
      link="LBS" />
    <axis
      xyz="0 0 0" />
  </joint>
  <link
    name="LBW">
    <inertial>
      <origin
        xyz="6.93889390390723E-18 5.55111512312578E-17 -2.77555756156289E-17"
        rpy="0 0 0" />
      <mass
        value="0.299097213540614" />
      <inertia
        ixx="0.000107128427988291"
        ixy="1.42968110446032E-21"
        ixz="-1.71146822692726E-22"
        iyy="0.000109833959413418"
        iyz="-8.66233287245744E-20"
        izz="0.000107128427988291" />
    </inertial>
    <visual>
      <origin
        xyz="0 0 0"
        rpy="0 0 0" />
      <geometry>
        <mesh
          filename="package://lide/meshes/LBW.STL" />
      </geometry>
      <material
        name="">
        <color
          rgba="0.898039215686275 0.917647058823529 0.929411764705882 1" />
      </material>
    </visual>
    <collision>
      <origin
        xyz="0 0 0"
        rpy="0 0 0" />
      <geometry>
        <mesh
          filename="package://lide/meshes/LBW.STL" />
      </geometry>
    </collision>
  </link>
  <joint
    name="LBW"
    type="revolute">
    <origin
      xyz="0 -0.055738 0"
      rpy="3.1416 0 1.5708" />
    <parent
      link="LBS" />
    <child
      link="LBW" />
    <axis
      xyz="0 1 0" />
    <limit
      lower="0"
      upper="0"
      effort="0"
      velocity="0" />
    <dynamics
      damping="0.001" />
  </joint>
  <link
    name="RBS">
    <inertial>
      <origin
        xyz="-4.79882529547115E-10 -0.023473389822872 -1.16815015993588E-09"
        rpy="0 0 0" />
      <mass
        value="0.083535872081433" />
      <inertia
        ixx="7.72968060896301E-05"
        ixy="-8.60478108456705E-13"
        ixz="1.40586703451147E-13"
        iyy="5.13820931926882E-05"
        iyz="-5.06559895608358E-12"
        izz="7.73952626484253E-05" />
    </inertial>
    <visual>
      <origin
        xyz="0 0 0"
        rpy="0 0 0" />
      <geometry>
        <mesh
          filename="package://lide/meshes/RBS.STL" />
      </geometry>
      <material
        name="">
        <color
          rgba="0.898039215686275 0.917647058823529 0.929411764705882 1" />
      </material>
    </visual>
    <collision>
      <origin
        xyz="0 0 0"
        rpy="0 0 0" />
      <geometry>
        <mesh
          filename="package://lide/meshes/RBS.STL" />
      </geometry>
    </collision>
  </link>
  <joint
    name="RBS"
    type="fixed">
    <origin
      xyz="-0.201999999999999 -0.0620027936477575 -0.0125623205686228"
      rpy="1.5707963267949 0 1.5707963267949" />
    <parent
      link="base_link" />
    <child
      link="RBS" />
    <axis
      xyz="0 0 0" />
  </joint>
  <link
    name="RBW">
    <inertial>
      <origin
        xyz="0 -2.08166817117217E-17 0"
        rpy="0 0 0" />
      <mass
        value="0.299097213540614" />
      <inertia
        ixx="0.000107128427988291"
        ixy="-1.3051765239872E-21"
        ixz="-5.50306717919325E-22"
        iyy="0.000109833959413418"
        iyz="-8.65899768022764E-20"
        izz="0.000107128427988291" />
    </inertial>
    <visual>
      <origin
        xyz="0 0 0"
        rpy="0 0 0" />
      <geometry>
        <mesh
          filename="package://lide/meshes/RBW.STL" />
      </geometry>
      <material
        name="">
        <color
          rgba="0.898039215686275 0.917647058823529 0.929411764705882 1" />
      </material>
    </visual>
    <collision>
      <origin
        xyz="0 0 0"
        rpy="0 0 0" />
      <geometry>
        <mesh
          filename="package://lide/meshes/RBW.STL" />
      </geometry>
    </collision>
  </link>
  <joint
    name="RBW"
    type="revolute">
    <origin
      xyz="0 -0.055738 0"
      rpy="0 0 -1.5708" />
    <parent
      link="RBS" />
    <child
      link="RBW" />
    <axis
      xyz="0 1 0" />
    <limit
      lower="0"
      upper="0"
      effort="0"
      velocity="0" />
    <dynamics
      damping="0.001" />
  </joint>
  <link
    name="fcam">
    <inertial>
      <origin
        xyz="-0.0115544746517359 -2.64429642850283E-06 0.00129029302682174"
        rpy="0 0 0" />
      <mass
        value="0.0436119957238952" />
      <inertia
        ixx="2.35707061906175E-05"
        ixy="-1.01842273865778E-09"
        ixz="2.17585832536658E-08"
        iyy="4.29479050056035E-06"
        iyz="-8.85018118760175E-10"
        izz="2.21058153511886E-05" />
    </inertial>
    <visual>
      <origin
        xyz="0 0 0"
        rpy="0 0 0" />
      <geometry>
        <mesh
          filename="package://lide/meshes/fcam.STL" />
      </geometry>
      <material
        name="">
        <color
          rgba="0.792156862745098 0.819607843137255 0.933333333333333 1" />
      </material>
    </visual>
    <collision>
      <origin
        xyz="0 0 0"
        rpy="0 0 0" />
      <geometry>
        <mesh
          filename="package://lide/meshes/fcam.STL" />
      </geometry>
    </collision>
  </link>
  <joint
    name="fcam"
    type="fixed">
    <origin
      xyz="-0.0038823 0.083 0.12982"
      rpy="0 0.2618 0" />
    <parent
      link="base_link" />
    <child
      link="fcam" />
    <axis
      xyz="0 0 0" />
  </joint>
  <link
    name="bcam">
    <inertial>
      <origin
        xyz="-0.02010346452991 -2.64354903287134E-06 -0.00725869505663598"
        rpy="0 0 0" />
      <mass
        value="0.0436119949785286" />
      <inertia
        ixx="2.35707056099601E-05"
        ixy="-1.01834758005623E-09"
        ixz="2.17579332532715E-08"
        iyy="4.29479078276665E-06"
        iyz="-8.85484503962031E-10"
        izz="2.21058144654638E-05" />
    </inertial>
    <visual>
      <origin
        xyz="0 0 0"
        rpy="0 0 0" />
      <geometry>
        <mesh
          filename="package://lide/meshes/bcam.STL" />
      </geometry>
      <material
        name="">
        <color
          rgba="0.792156862745098 0.819607843137255 0.933333333333333 1" />
      </material>
    </visual>
    <collision>
      <origin
        xyz="0 0 0"
        rpy="0 0 0" />
      <geometry>
        <mesh
          filename="package://lide/meshes/bcam.STL" />
      </geometry>
    </collision>
  </link>
  <joint
    name="bcam"
    type="fixed">
    <origin
      xyz="0 0.083 0.091232"
      rpy="0 0.7854 0" />
    <parent
      link="base_link" />
    <child
      link="bcam" />
    <axis
      xyz="0 0 0" />
  </joint>
  <link
    name="Lidar">
    <inertial>
      <origin
        xyz="0.0135233595886409 0.000461955982206302 -0.028764885495051"
        rpy="0 0 0" />
      <mass
        value="0.0730845717569496" />
      <inertia
        ixx="1.95808757419765E-05"
        ixy="-1.03933585736234E-07"
        ixz="-4.28391168396098E-07"
        iyy="2.41250079666672E-05"
        iyz="9.42710206434141E-09"
        izz="4.14184516368183E-05" />
    </inertial>
    <visual>
      <origin
        xyz="0 0 0"
        rpy="0 0 0" />
      <geometry>
        <mesh
          filename="package://lide/meshes/Lidar.STL" />
      </geometry>
      <material
        name="">
        <color
          rgba="0.792156862745098 0.819607843137255 0.933333333333333 1" />
      </material>
    </visual>
    <collision>
      <origin
        xyz="0 0 0"
        rpy="0 0 0" />
      <geometry>
        <mesh
          filename="package://lide/meshes/Lidar.STL" />
      </geometry>
    </collision>
  </link>
  <joint
    name="Lidar"
    type="fixed">
    <origin
      xyz="-0.19458 0.082006 0.2065"
      rpy="0 0 0" />
    <parent
      link="base_link" />
    <child
      link="Lidar" />
    <axis
      xyz="0 0 0" />
  </joint>
  <link
    name="bacam">
    <inertial>
      <origin
        xyz="-0.0115544745937307 -2.64413025866106E-06 0.00129029332987485"
        rpy="0 0 0" />
      <mass
        value="0.0436119955853512" />
      <inertia
        ixx="2.35707060477621E-05"
        ixy="-1.01845901670897E-09"
        ixz="2.17584641953356E-08"
        iyy="4.29479042104483E-06"
        iyz="-8.85026498666259E-10"
        izz="2.2105815279964E-05" />
    </inertial>
    <visual>
      <origin
        xyz="0 0 0"
        rpy="0 0 0" />
      <geometry>
        <mesh
          filename="package://lide/meshes/bacam.STL" />
      </geometry>
      <material
        name="">
        <color
          rgba="0.792156862745098 0.819607843137255 0.933333333333333 1" />
      </material>
    </visual>
    <collision>
      <origin
        xyz="0 0 0"
        rpy="0 0 0" />
      <geometry>
        <mesh
          filename="package://lide/meshes/bacam.STL" />
      </geometry>
    </collision>
  </link>
  <joint
    name="bacam"
    type="fixed">
    <origin
      xyz="-0.24887 0.083 0.12838"
      rpy="0 0.34907 3.1416" />
    <parent
      link="base_link" />
    <child
      link="bacam" />
    <axis
      xyz="0 0 0" />
  </joint>
  <link
    name="imu_link">
    <inertial>
      <origin
        xyz="0.00385022026093959 6.239840080563E-05 -0.00103377575234337"
        rpy="0 0 0" />
      <mass
        value="0.00189180567975737" />
      <inertia
        ixx="7.79431263454135E-08"
        ixy="1.39214190556514E-10"
        ixz="1.54511633252899E-11"
        iyy="4.85473464623125E-08"
        iyz="-6.30099051334897E-11"
        izz="1.25233585370532E-07" />
    </inertial>
    <visual>
      <origin
        xyz="0 0 0"
        rpy="0 0 0" />
      <geometry>
        <mesh
          filename="package://lide/meshes/imu_link.STL" />
      </geometry>
      <material
        name="">
        <color
          rgba="0.898039215686275 0.917647058823529 0.929411764705882 1" />
      </material>
    </visual>
    <collision>
      <origin
        xyz="0 0 0"
        rpy="0 0 0" />
      <geometry>
        <mesh
          filename="package://lide/meshes/imu_link.STL" />
      </geometry>
    </collision>
  </link>
  <joint
    name="imu_link"
    type="fixed">
    <origin
      xyz="-0.039 0.083 0.155"
      rpy="0 0 0" />
    <parent
      link="base_link" />
    <child
      link="imu_link" />
    <axis
      xyz="0 0 0" />
  </joint>
</robot>